Workbook
Name Slicer_Diabetes_Status: #N/A
Name Slicer_Weight_Status: #N/A

Sheet Medical Examinations
A1: Customer ID | B1: BMI | C1: Weight Status | D1: HBA1C | E1: Diabetes Status | F1: Heart Issues | G1: Any Transplants | H1: Cancer history | I1: NumberOfMajorSurgeries | J1: smoker
A2: ID1 | B2: 47.41 | C2: Obesity | D2: 7.47 | E2: Diabetes | F2: No | G2: No | H2: No | I2: 0 | J2: Yes
A3: ID2 | B3: 30.36 | C3: Obesity | D3: 5.77 | E3: Prediabetes | F3: No | G3: No | H3: No | I3: 0 | J3: Yes
A4: ID3 | B4: 34.485 | C4: Obesity | D4: 11.87 | E4: Diabetes | F4: Yes | G4: No | H4: No | I4: 2 | J4: Yes
A5: ID4 | B5: 38.095 | C5: Obesity | D5: 6.05 | E5: Prediabetes | F5: No | G5: No | H5: No | I5: 0 | J5: Yes
A6: ID5 | B6: 35.53 | C6: Obesity | D6: 5.45 | E6: Normal | F6: No | G6: No | H6: No | I6: 0 | J6: Yes
A7: ID6 | B7: 32.8 | C7: Obesity | D7: 6.59 | E7: Diabetes | F7: No | G7: No | H7: No | I7: 0 | J7: Yes
A8: ID7 | B8: 36.4 | C8: Obesity | D8: 6.07 | E8: Prediabetes | F8: No | G8: No | H8: No | I8: 0 | J8: Yes
A9: ID8 | B9: 36.96 | C9: Obesity | D9: 7.93 | E9: Diabetes | F9: No | G9: No | H9: No | I9: 3 | J9: Yes
A10: ID9 | B10: 41.14 | C10: Obesity | D10: 9.58 | E10: Diabetes | F10: Yes | G10: No | H10: Yes | I10: 1 | J10: Yes
A11: ID10 | B11: 38.06 | C11: Obesity | D11: 10.79 | E11: Diabetes | F11: No | G11: No | H11: No | I11: 0 | J11: Yes
A12: ID11 | B12: 37.7 | C12: Obesity | D12: 5.96 | E12: Prediabetes | F12: Yes | G12: No | H12: No | I12: 2 | J12: Yes
A13: ID12 | B13: 42.13 | C13: Obesity | D13: 11.9 | E13: Diabetes | F13: No | G13: No | H13: No | I13: 0 | J13: Yes
... A2336: ID2335 | B2336: 17.58 | C2336: Underweight | D2336: 4.51 | E2336: Normal | F2336: No | G2336: No | H2336: No | I2336: 1 | J2336: No

Sheet Hospitalisation Details
A1: Customer ID | B1: year | C1: month | D1: date | E1: Date of Birth | F1: Date of Birth2 | G1: children | H1: Age | I1: charges | J1: Hospital tier | K1: City tier | L1: State ID
A2: ID2335 | B2: 1992 | C2: Jul | D2: 9 | E2: =_xlfn.CONCAT(Hospitalisation_Details[[#This Row],[date]],"-",Hospitalisation_Details[[#This Row],[month]],"-",Hospitalisation_Details[[#This Row],[year]]) -> 9-Jul-1992 | F2: =TEXT(Hospitalisation_Details[[#This Row],[Date of Birth]],"dd-mm-yy") -> 09-07-92 | G2: 0 | H2: =DATEDIF(Hospitalisation_Details[[#This Row],[Date of Birth2]],DATE(2023,6,8),"y") -> 30 | I2: 563.84 | J2: Tier - 2 | K2: Tier - 3 | L2: R1013
A3: ID2334 | B3: 1992 | C3: Nov | D3: 30 | E3: =_xlfn.CONCAT(Hospitalisation_Details[[#This Row],[date]],"-",Hospitalisation_Details[[#This Row],[month]],"-",Hospitalisation_Details[[#This Row],[year]]) -> 30-Nov-1992 | F3: =TEXT(Hospitalisation_Details[[#This Row],[Date of Birth]],"dd-mm-yy") -> 30-11-92 | G3: 0 | H3: =DATEDIF(Hospitalisation_Details[[#This Row],[Date of Birth2]],DATE(2023,6,8),"y") -> 30 | I3: 570.62 | J3: Tier - 2 | K3: Tier - 1 | L3: R1013
A4: ID2333 | B4: 1993 | C4: Jun | D4: 30 | E4: =_xlfn.CONCAT(Hospitalisation_Details[[#This Row],[date]],"-",Hospitalisation_Details[[#This Row],[month]],"-",Hospitalisation_Details[[#This Row],[year]]) -> 30-Jun-1993 | F4: =TEXT(Hospitalisation_Details[[#This Row],[Date of Birth]],"dd-mm-yy") -> 30-06-93 | G4: 0 | H4: =DATEDIF(Hospitalisation_Details[[#This Row],[Date of Birth2]],DATE(2023,6,8),"y") -> 29 | I4: 600 | J4: Tier - 2 | K4: Tier - 1 | L4: R1013
A5: ID2332 | B5: 1992 | C5: Sep | D5: 13 | E5: =_xlfn.CONCAT(Hospitalisation_Details[[#This Row],[date]],"-",Hospitalisation_Details[[#This Row],[month]],"-",Hospitalisation_Details[[#This Row],[year]]) -> 13-Sep-1992 | F5: =TEXT(Hospitalisation_Details[[#This Row],[Date of Birth]],"dd-mm-yy") -> 13-09-92 | G5: 0 | H5: =DATEDIF(Hospitalisation_Details[[#This Row],[Date of Birth2]],DATE(2023,6,8),"y") -> 30 | I5: 604.54 | J5: Tier - 3 | K5: Tier - 3 | L5: R1013
A6: ID2331 | B6: 1998 | C6: Jul | D6: 27 | E6: =_xlfn.CONCAT(Hospitalisation_Details[[#This Row],[date]],"-",Hospitalisation_Details[[#This Row],[month]],"-",Hospitalisation_Details[[#This Row],[year]]) -> 27-Jul-1998 | F6: =TEXT(Hospitalisation_Details[[#This Row],[Date of Birth]],"dd-mm-yy") -> 27-07-98 | G6: 0 | H6: =DATEDIF(Hospitalisation_Details[[#This Row],[Date of Birth2]],DATE(2023,6,8),"y") -> 24 | I6: 637.26 | J6: Tier - 3 | K6: Tier - 3 | L6: R1013
A7: ID2330 | B7: 2001 | C7: Nov | D7: 20 | E7: =_xlfn.CONCAT(Hospitalisation_Details[[#This Row],[date]],"-",Hospitalisation_Details[[#This Row],[month]],"-",Hospitalisation_Details[[#This Row],[year]]) -> 20-Nov-2001 | F7: =TEXT(Hospitalisation_Details[[#This Row],[Date of Birth]],"dd-mm-yy") -> 20-11-01 | G7: 0 | H7: =DATEDIF(Hospitalisation_Details[[#This Row],[Date of Birth2]],DATE(2023,6,8),"y") -> 21 | I7: 646.14 | J7: Tier - 3 | K7: Tier - 3 | L7: R1012
A8: ID2329 | B8: 1993 | C8: Jun | D8: 1 | E8: =_xlfn.CONCAT(Hospitalisation_Details[[#This Row],[date]],"-",Hospitalisation_Details[[#This Row],[month]],"-",Hospitalisation_Details[[#This Row],[year]]) -> 1-Jun-1993 | F8: =TEXT(Hospitalisation_Details[[#This Row],[Date of Birth]],"dd-mm-yy") -> 01-06-93 | G8: 0 | H8: =DATEDIF(Hospitalisation_Details[[#This Row],[Date of Birth2]],DATE(2023,6,8),"y") -> 30 | I8: 650 | J8: Tier - 3 | K8: Tier - 3 | L8: R1013
A9: ID2328 | B9: 1995 | C9: Jul | D9: 4 | E9: =_xlfn.CONCAT(Hospitalisation_Details[[#This Row],[date]],"-",Hospitalisation_Details[[#This Row],[month]],"-",Hospitalisation_Details[[#This Row],[year]]) -> 4-Jul-1995 | F9: =TEXT(Hospitalisation_Details[[#This Row],[Date of Birth]],"dd-mm-yy") -> 04-07-95 | G9: 0 | H9: =DATEDIF(Hospitalisation_Details[[#This Row],[Date of Birth2]],DATE(2023,6,8),"y") -> 27 | I9: 650 | J9: Tier - 3 | K9: Tier - 3 | L9: R1013
A10: ID2327 | B10: 2002 | C10: Nov | D10: 29 | E10: =_xlfn.CONCAT(Hospitalisation_Details[[#This Row],[date]],"-",Hospitalisation_Details[[#This Row],[month]],"-",Hospitalisation_Details[[#This Row],[year]]) -> 29-Nov-2002 | F10: =TEXT(Hospitalisation_Details[[#This Row],[Date of Birth]],"dd-mm-yy") -> 29-11-02 | G10: 0 | H10: =DATEDIF(Hospitalisation_Details[[#This Row],[Date of Birth2]],DATE(2023,6,8),"y") -> 20 | I10: 668 | J10: Tier - 3 | K10: Tier - 2 | L10: R1012
A11: ID2326 | B11: 1997 | C11: Nov | D11: 9 | E11: =_xlfn.CONCAT(Hospitalisation_Details[[#This Row],[date]],"-",Hospitalisation_Details[[#This Row],[month]],"-",Hospitalisation_Details[[#This Row],[year]]) -> 9-Nov-1997 | F11: =TEXT(Hospitalisation_Details[[#This Row],[Date of Birth]],"dd-mm-yy") -> 09-11-97 | G11: 0 | H11: =DATEDIF(Hospitalisation_Details[[#This Row],[Date of Birth2]],DATE(2023,6,8),"y") -> 25 | I11: 670 | J11: Tier - 3 | K11: Tier - 3 | L11: R1013
A12: ID2325 | B12: 2001 | C12: Sep | D12: 12 | E12: =_xlfn.CONCAT(Hospitalisation_Details[[#This Row],[date]],"-",Hospitalisation_Details[[#This Row],[month]],"-",Hospitalisation_Details[[#This Row],[year]]) -> 12-Sep-2001 | F12: =TEXT(Hospitalisation_Details[[#This Row],[Date of Birth]],"dd-mm-yy") -> 12-09-01 | G12: 0 | H12: =DATEDIF(Hospitalisation_Details[[#This Row],[Date of Birth2]],DATE(2023,6,8),"y") -> 21 | I12: 687.54 | J12: Tier - 3 | K12: Tier - 2 | L12: R1013
A13: ID2324 | B13: 1999 | C13: Dec | D13: 26 | E13: =_xlfn.CONCAT(Hospitalisation_Details[[#This Row],[date]],"-",Hospitalisation_Details[[#This Row],[month]],"-",Hospitalisation_Details[[#This Row],[year]]) -> 26-Dec-1999 | F13: =TEXT(Hospitalisation_Details[[#This Row],[Date of Birth]],"dd-mm-yy") -> 26-12-99 | G13: 0 | H13: =DATEDIF(Hospitalisation_Details[[#This Row],[Date of Birth2]],DATE(2023,6,8),"y") -> 23 | I13: 700 | J13: Tier - 2 | K13: Tier - 3 | L13: R1013
... A1050: ID1290 | B1050: 1977 | C1050: Jul | D1050: 26 | E1050: =_xlfn.CONCAT(Hospitalisation_Details[[#This Row],[date]],"-",Hospitalisation_Details[[#This Row],[month]],"-",Hospitalisation_Details[[#This Row],[year]]) -> 26-Jul-1977 | F1050: =TEXT(Hospitalisation_Details[[#This Row],[Date of Birth]],"dd-mm-yy") -> 26-07-77 | G1050: 2 | H1050: =DATEDIF(Hospitalisation_Details[[#This Row],[Date of Birth2]],DATE(2023,6,8),"y") -> 45 | I1050: 8527.53 | J1050: Tier - 2 | K1050: Tier - 2 | L1050: R1013
A1051: ID1289 | C1051: Jul | D1051: 24 | E1051: =_xlfn.CONCAT(Hospitalisation_Details[[#This Row],[date]],"-",Hospitalisation_Details[[#This Row],[month]],"-",Hospitalisation_Details[[#This Row],[year]]) -> 24-Jul- | F1051: =TEXT(Hospitalisation_Details[[#This Row],[Date of Birth]],"dd-mm-yy") -> 24-Jul- | G1051: 0 | H1051: =DATEDIF(Hospitalisation_Details[[#This Row],[Date of Birth2]],DATE(2023,6,8),"y") -> #VALUE! | I1051: 8534.67 | J1051: Tier - 2 | K1051: Tier - 3 | L1051: R1024
A1052: ID1288 | B1052: 1981 | C1052: Dec | D1052: 27 | E1052: =_xlfn.CONCAT(Hospitalisation_Details[[#This Row],[date]],"-",Hospitalisation_Details[[#This Row],[month]],"-",Hospitalisation_Details[[#This Row],[year]]) -> 27-Dec-1981 | F1052: =TEXT(Hospitalisation_Details[[#This Row],[Date of Birth]],"dd-mm-yy") -> 27-12-81 | G1052: 3 | H1052: =DATEDIF(Hospitalisation_Details[[#This Row],[Date of Birth2]],DATE(2023,6,8),"y") -> 41 | I1052: 8538.29 | J1052: Tier - 2 | K1052: Tier - 3 | L1052: R1024
A1053: ID1287 | B1053: 1975 | C1053: Nov | D1053: 6 | E1053: =_xlfn.CONCAT(Hospitalisation_Details[[#This Row],[date]],"-",Hospitalisation_Details[[#This Row],[month]],"-",Hospitalisation_Details[[#This Row],[year]]) -> 6-Nov-1975 | F1053: =TEXT(Hospitalisation_Details[[#This Row],[Date of Birth]],"dd-mm-yy") -> 06-11-75 | G1053: 1 | H1053: =DATEDIF(Hospitalisation_Details[[#This Row],[Date of Birth2]],DATE(2023,6,8),"y") -> 47 | I1053: 8539.67 | J1053: Tier - 2 | K1053: Tier - 3 | L1053: R1011
A1054: ID1286 | C1054: Dec | D1054: 12 | E1054: =_xlfn.CONCAT(Hospitalisation_Details[[#This Row],[date]],"-",Hospitalisation_Details[[#This Row],[month]],"-",Hospitalisation_Details[[#This Row],[year]]) -> 12-Dec- | F1054: =TEXT(Hospitalisation_Details[[#This Row],[Date of Birth]],"dd-mm-yy") -> 12-Dec- | G1054: 1 | H1054: =DATEDIF(Hospitalisation_Details[[#This Row],[Date of Birth2]],DATE(2023,6,8),"y") -> #VALUE! | I1054: 8547.69 | J1054: Tier - 2 | K1054: Tier - 1 | L1054: R1013
A1055: ID1285 | B1055: 1975 | C1055: Aug | D1055: 6 | E1055: =_xlfn.CONCAT(Hospitalisation_Details[[#This Row],[date]],"-",Hospitalisation_Details[[#This Row],[month]],"-",Hospitalisation_Details[[#This Row],[year]]) -> 6-Aug-1975 | F1055: =TEXT(Hospitalisation_Details[[#This Row],[Date of Birth]],"dd-mm-yy") -> 06-08-75 | G1055: 1 | H1055: =DATEDIF(Hospitalisation_Details[[#This Row],[Date of Birth2]],DATE(2023,6,8),"y") -> 47 | I1055: 8551.35 | J1055: Tier - 2 | K1055: Tier - 2 | L1055: R1011
A1056: ID1284 | B1056: 1975 | C1056: Aug | D1056: 21 | E1056: =_xlfn.CONCAT(Hospitalisation_Details[[#This Row],[date]],"-",Hospitalisation_Details[[#This Row],[month]],"-",Hospitalisation_Details[[#This Row],[year]]) -> 21-Aug-1975 | F1056: =TEXT(Hospitalisation_Details[[#This Row],[Date of Birth]],"dd-mm-yy") -> 21-08-75 | G1056: 1 | H1056: =DATEDIF(Hospitalisation_Details[[#This Row],[Date of Birth2]],DATE(2023,6,8),"y") -> 47 | I1056: 8556.91 | J1056: Tier - 2 | K1056: Tier - 1 | L1056: R1011
A1057: ID1283 | B1057: 1988 | C1057: Sep | D1057: 21 | E1057: =_xlfn.CONCAT(Hospitalisation_Details[[#This Row],[date]],"-",Hospitalisation_Details[[#This Row],[month]],"-",Hospitalisation_Details[[#This Row],[year]]) -> 21-Sep-1988 | F1057: =TEXT(Hospitalisation_Details[[#This Row],[Date of Birth]],"dd-mm-yy") -> 21-09-88 | G1057: 3 | H1057: =DATEDIF(Hospitalisation_Details[[#This Row],[Date of Birth2]],DATE(2023,6,8),"y") -> 34 | I1057: 8567.25 | J1057: Tier - 2 | K1057: Tier - 1 | L1057: R1012
A1058: ID1282 | B1058: 1975 | C1058: Sep | D1058: 26 | E1058: =_xlfn.CONCAT(Hospitalisation_Details[[#This Row],[date]],"-",Hospitalisation_Details[[#This Row],[month]],"-",Hospitalisation_Details[[#This Row],[year]]) -> 26-Sep-1975 | F1058: =TEXT(Hospitalisation_Details[[#This Row],[Date of Birth]],"dd-mm-yy") -> 26-09-75 | G1058: 1 | H1058: =DATEDIF(Hospitalisation_Details[[#This Row],[Date of Birth2]],DATE(2023,6,8),"y") -> 47 | I1058: 8569.86 | J1058: Tier - 2 | K1058: Tier - 3 | L1058: R1013
A1059: ID1281 | B1059: 1982 | C1059: Dec | D1059: 6 | E1059: =_xlfn.CONCAT(Hospitalisation_Details[[#This Row],[date]],"-",Hospitalisation_Details[[#This Row],[month]],"-",Hospitalisation_Details[[#This Row],[year]]) -> 6-Dec-1982 | F1059: =TEXT(Hospitalisation_Details[[#This Row],[Date of Birth]],"dd-mm-yy") -> 06-12-82 | G1059: 3 | H1059: =DATEDIF(Hospitalisation_Details[[#This Row],[Date of Birth2]],DATE(2023,6,8),"y") -> 40 | I1059: 8572.04 | J1059: Tier - 2 | K1059: Tier - 2 | L1059: R1021
A1060: ID1280 | B1060: 1987 | C1060: Nov | D1060: 11 | E1060: =_xlfn.CONCAT(Hospitalisation_Details[[#This Row],[date]],"-",Hospitalisation_Details[[#This Row],[month]],"-",Hospitalisation_Details[[#This Row],[year]]) -> 11-Nov-1987 | F1060: =TEXT(Hospitalisation_Details[[#This Row],[Date of Birth]],"dd-mm-yy") -> 11-11-87 | G1060: 3 | H1060: =DATEDIF(Hospitalisation_Details[[#This Row],[Date of Birth2]],DATE(2023,6,8),"y") -> 35 | I1060: 8573.3 | J1060: Tier - 2 | K1060: Tier - 2 | L1060: R1021
A1061: ID1279 | B1061: 1983 | C1061: Dec | D1061: 30 | E1061: =_xlfn.CONCAT(Hospitalisation_Details[[#This Row],[date]],"-",Hospitalisation_Details[[#This Row],[month]],"-",Hospitalisation_Details[[#This Row],[year]]) -> 30-Dec-1983 | F1061: =TEXT(Hospitalisation_Details[[#This Row],[Date of Birth]],"dd-mm-yy") -> 30-12-83 | G1061: 5 | H1061: =DATEDIF(Hospitalisation_Details[[#This Row],[Date of Birth2]],DATE(2023,6,8),"y") -> 39 | I1061: 8582.3 | J1061: Tier - 2 | K1061: Tier - 1 | L1061: R1013
A1062: ID1278 | B1062: 1983 | C1062: Jul | D1062: 25 | E1062: =_xlfn.CONCAT(Hospitalisation_Details[[#This Row],[date]],"-",Hospitalisation_Details[[#This Row],[month]],"-",Hospitalisation_Details[[#This Row],[year]]) -> 25-Jul-1983 | F1062: =TEXT(Hospitalisation_Details[[#This Row],[Date of Birth]],"dd-mm-yy") -> 25-07-83 | G1062: 5 | H1062: =DATEDIF(Hospitalisation_Details[[#This Row],[Date of Birth2]],DATE(2023,6,8),"y") -> 39 | I1062: 8596.83 | J1062: Tier - 2 | K1062: Tier - 3 | L1062: R1013
A1063: ID1277 | B1063: 1973 | C1063: Jul | D1063: 11 | E1063: =_xlfn.CONCAT(Hospitalisation_Details[[#This Row],[date]],"-",Hospitalisation_Details[[#This Row],[month]],"-",Hospitalisation_Details[[#This Row],[year]]) -> 11-Jul-1973 | F1063: =TEXT(Hospitalisation_Details[[#This Row],[Date of Birth]],"dd-mm-yy") -> 11-07-73 | G1063: 0 | H1063: =DATEDIF(Hospitalisation_Details[[#This Row],[Date of Birth2]],DATE(2023,6,8),"y") -> 49 | I1063: 8601.33 | J1063: Tier - 2 | K1063: Tier - 1 | L1063: R1013
A1064: ID1276 | B1064: 1977 | C1064: Sep | D1064: 24 | E1064: =_xlfn.CONCAT(Hospitalisation_Details[[#This Row],[date]],"-",Hospitalisation_Details[[#This Row],[month]],"-",Hospitalisation_Details[[#This Row],[year]]) -> 24-Sep-1977 | F1064: =TEXT(Hospitalisation_Details[[#This Row],[Date of Birth]],"dd-mm-yy") -> 24-09-77 | G1064: 2 | H1064: =DATEDIF(Hospitalisation_Details[[#This Row],[Date of Birth2]],DATE(2023,6,8),"y") -> 45 | I1064: 8603.82 | J1064: Tier - 2 | K1064: Tier - 1 | L1064: R1019
A1065: ID1275 | B1065: 1977 | C1065: Nov | D1065: 12 | E1065: =_xlfn.CONCAT(Hospitalisation_Details[[#This Row],[date]],"-",Hospitalisation_Details[[#This Row],[month]],"-",Hospitalisation_Details[[#This Row],[year]]) -> 12-Nov-1977 | F1065: =TEXT(Hospitalisation_Details[[#This Row],[Date of Birth]],"dd-mm-yy") -> 12-11-77 | G1065: 2 | H1065: =DATEDIF(Hospitalisation_Details[[#This Row],[Date of Birth2]],DATE(2023,6,8),"y") -> 45 | I1065: 8604.48 | J1065: Tier - 3 | K1065: Tier - 2 | L1065: R1016
A1066: ID1274 | B1066: 1977 | C1066: Oct | D1066: 15 | E1066: =_xlfn.CONCAT(Hospitalisation_Details[[#This Row],[date]],"-",Hospitalisation_Details[[#This Row],[month]],"-",Hospitalisation_Details[[#This Row],[year]]) -> 15-Oct-1977 | F1066: =TEXT(Hospitalisation_Details[[#This Row],[Date of Birth]],"dd-mm-yy") -> 15-10-77 | G1066: 3 | H1066: =DATEDIF(Hospitalisation_Details[[#This Row],[Date of Birth2]],DATE(2023,6,8),"y") -> 45 | I1066: 8605.36 | J1066: Tier - 2 | K1066: Tier - 2 | L1066: R1013
... A2344: ID1 | B2344: 1968 | C2344: Oct | D2344: 12 | E2344: =_xlfn.CONCAT(Hospitalisation_Details[[#This Row],[date]],"-",Hospitalisation_Details[[#This Row],[month]],"-",Hospitalisation_Details[[#This Row],[year]]) -> 12-Oct-1968 | F2344: =TEXT(Hospitalisation_Details[[#This Row],[Date of Birth]],"dd-mm-yy") -> 12-10-68 | G2344: 0 | H2344: =DATEDIF(Hospitalisation_Details[[#This Row],[Date of Birth2]],DATE(2023,6,8),"y") -> 54 | I2344: 63770.43 | J2344: Tier - 1 | K2344: Tier - 3 | L2344: R1013

Sheet Customer Names
A1: Customer ID | B1: Title | C1: First Name | D1: Last Name
A2: ID1 | B2: Ms. | C2: Kelly | D2: Hawks
A3: ID2 | B3: Mr. | C3: Matthew D | D3: Lehner
A4: ID3 | B4: Mr. | C4: Phil | D4: Lu
A5: ID4 | B5: Ms. | C5: Kelsey | D5: Osborne
A6: ID5 | B6: Ms. | C6: Kristyn | D6: Kadala
A7: ID6 | B7: Mr. | C7: Russell B. | D7: Baker
A8: ID7 | B8: Mr. | C8: Scott | D8: Macpherson
A9: ID8 | B9: Mr. | C9: Stephen | D9: Hallman
A10: ID9 | B10: Mr. | C10: Patrick R. | D10: Moran
A11: ID10 | B11: Ms. | C11: Brooke N. | D11: Benner
A12: ID11 | B12: Ms. | C12: Paola Andrea | D12: Fierro Vargas
... A2336: ID2335 | B2336: Mr. | C2336: Aaron K | D2336: German

Sheet Health Care
A1: Customer ID | B1: Column1 | C1: Title | D1: First Name | E1: Last Name | F1: Date of Birth | G1: Age | H1: State ID | I1: Hospital tier | J1: City tier | K1: charges | L1: BMI | M1: Weight Status | N1: HBA1C | O1: Diabetes Status | P1: Heart Issues | Q1: Any Transplants | R1: Cancer history | S1: Number Of Major Surgeries | T1: smoker
A2: ID1 | B2: Id1 | C2: Ms. | D2: Kelly | E2: Hawks | F2: =VLOOKUP(Hospitalisation_Details[[#This Row],[Customer ID]],Hospitalisation_Details[#All],6,FALSE) -> 09-07-92 | G2: =VLOOKUP(Hospitalisation_Details[[#This Row],[Customer ID]],Hospitalisation_Details[#All],8,FALSE) -> 30 | H2: =VLOOKUP(Hospitalisation_Details[[#This Row],[Customer ID]],Hospitalisation_Details[#All],12,FALSE) -> R1013 | I2: =VLOOKUP(Hospitalisation_Details[[#This Row],[Customer ID]],Hospitalisation_Details[#All],12,FALSE) -> R1013 | J2: =VLOOKUP(Hospitalisation_Details[[#This Row],[Customer ID]],Hospitalisation_Details[#All],11,FALSE) -> Tier - 3 | K2: =VLOOKUP(Hospitalisation_Details[[#This Row],[Customer ID]],Hospitalisation_Details[#All],9,FALSE) -> 563.84 | L2: =VLOOKUP(Medical_Examinations[[#This Row],[Customer ID]],Medical_Examinations[#All],2,FALSE) -> 47.41 | M2: =VLOOKUP(Medical_Examinations[[#This Row],[Customer ID]],Medical_Examinations[#All],3,FALSE) -> Obesity | N2: =VLOOKUP(Medical_Examinations[[#This Row],[Customer ID]],Medical_Examinations[#All],4,FALSE) -> 7.47 | O2: =VLOOKUP(Medical_Examinations[[#This Row],[Customer ID]],Medical_Examinations[#All],5,FALSE) -> Diabetes | P2: =VLOOKUP(Medical_Examinations[[#This Row],[Customer ID]],Medical_Examinations[#All],6,FALSE) -> No | Q2: =VLOOKUP(Medical_Examinations[[#This Row],[Customer ID]],Medical_Examinations[#All],7,FALSE) -> No | R2: =VLOOKUP(Medical_Examinations[[#This Row],[Customer ID]],Medical_Examinations[#All],8,FALSE) -> No | S2: =VLOOKUP(Medical_Examinations[[#This Row],[Customer ID]],Medical_Examinations[#All],9,FALSE) -> 0 | T2: =VLOOKUP(Medical_Examinations[[#This Row],[Customer ID]],'Medical Examinations'!A1:J2336,10,FALSE) -> Yes
A3: ID2 | B3: Id2 | C3: Mr. | D3: Matthew D | E3: Lehner | F3: =VLOOKUP(Hospitalisation_Details[[#This Row],[Customer ID]],Hospitalisation_Details[#All],6,FALSE) -> 30-11-92 | G3: =VLOOKUP(Hospitalisation_Details[[#This Row],[Customer ID]],Hospitalisation_Details[#All],8,FALSE) -> 30 | H3: =VLOOKUP(Hospitalisation_Details[[#This Row],[Customer ID]],Hospitalisation_Details[#All],12,FALSE) -> R1013 | I3: =VLOOKUP(Hospitalisation_Details[[#This Row],[Customer ID]],Hospitalisation_Details[#All],12,FALSE) -> R1013 | J3: =VLOOKUP(Hospitalisation_Details[[#This Row],[Customer ID]],Hospitalisation_Details[#All],11,FALSE) -> Tier - 1 | K3: =VLOOKUP(Hospitalisation_Details[[#This Row],[Customer ID]],Hospitalisation_Details[#All],9,FALSE) -> 570.62 | L3: =VLOOKUP(Medical_Examinations[[#This Row],[Customer ID]],Medical_Examinations[#All],2,FALSE) -> 30.36 | M3: =VLOOKUP(Medical_Examinations[[#This Row],[Customer ID]],Medical_Examinations[#All],3,FALSE) -> Obesity | N3: =VLOOKUP(Medical_Examinations[[#This Row],[Customer ID]],Medical_Examinations[#All],4,FALSE) -> 5.77 | O3: =VLOOKUP(Medical_Examinations[[#This Row],[Customer ID]],Medical_Examinations[#All],5,FALSE) -> Prediabetes | P3: =VLOOKUP(Medical_Examinations[[#This Row],[Customer ID]],Medical_Examinations[#All],6,FALSE) -> No | Q3: =VLOOKUP(Medical_Examinations[[#This Row],[Customer ID]],Medical_Examinations[#All],7,FALSE) -> No | R3: =VLOOKUP(Medical_Examinations[[#This Row],[Customer ID]],Medical_Examinations[#All],8,FALSE) -> No | S3: =VLOOKUP(Medical_Examinations[[#This Row],[Customer ID]],Medical_Examinations[#All],9,FALSE) -> 0 | T3: =VLOOKUP(Medical_Examinations[[#This Row],[Customer ID]],'Medical Examinations'!A2:J2337,10,FALSE) -> Yes
A4: ID3 | B4: Id3 | C4: Mr. | D4: Phil | E4: Lu | F4: =VLOOKUP(Hospitalisation_Details[[#This Row],[Customer ID]],Hospitalisation_Details[#All],6,FALSE) -> 30-06-93 | G4: =VLOOKUP(Hospitalisation_Details[[#This Row],[Customer ID]],Hospitalisation_Details[#All],8,FALSE) -> 29 | H4: =VLOOKUP(Hospitalisation_Details[[#This Row],[Customer ID]],Hospitalisation_Details[#All],12,FALSE) -> R1013 | I4: =VLOOKUP(Hospitalisation_Details[[#This Row],[Customer ID]],Hospitalisation_Details[#All],12,FALSE) -> R1013 | J4: =VLOOKUP(Hospitalisation_Details[[#This Row],[Customer ID]],Hospitalisation_Details[#All],11,FALSE) -> Tier - 1 | K4: =VLOOKUP(Hospitalisation_Details[[#This Row],[Customer ID]],Hospitalisation_Details[#All],9,FALSE) -> 600 | L4: =VLOOKUP(Medical_Examinations[[#This Row],[Customer ID]],Medical_Examinations[#All],2,FALSE) -> 34.485 | M4: =VLOOKUP(Medical_Examinations[[#This Row],[Customer ID]],Medical_Examinations[#All],3,FALSE) -> Obesity | N4: =VLOOKUP(Medical_Examinations[[#This Row],[Customer ID]],Medical_Examinations[#All],4,FALSE) -> 11.87 | O4: =VLOOKUP(Medical_Examinations[[#This Row],[Customer ID]],Medical_Examinations[#All],5,FALSE) -> Diabetes | P4: =VLOOKUP(Medical_Examinations[[#This Row],[Customer ID]],Medical_Examinations[#All],6,FALSE) -> Yes | Q4: =VLOOKUP(Medical_Examinations[[#This Row],[Customer ID]],Medical_Examinations[#All],7,FALSE) -> No | R4: =VLOOKUP(Medical_Examinations[[#This Row],[Customer ID]],Medical_Examinations[#All],8,FALSE) -> No | S4: =VLOOKUP(Medical_Examinations[[#This Row],[Customer ID]],Medical_Examinations[#All],9,FALSE) -> 2 | T4: =VLOOKUP(Medical_Examinations[[#This Row],[Customer ID]],'Medical Examinations'!A3:J2338,10,FALSE) -> Yes
A5: ID4 | B5: Id4 | C5: Ms. | D5: Kelsey | E5: Osborne | F5: =VLOOKUP(Hospitalisation_Details[[#This Row],[Customer ID]],Hospitalisation_Details[#All],6,FALSE) -> 13-09-92 | G5: =VLOOKUP(Hospitalisation_Details[[#This Row],[Customer ID]],Hospitalisation_Details[#All],8,FALSE) -> 30 | H5: =VLOOKUP(Hospitalisation_Details[[#This Row],[Customer ID]],Hospitalisation_Details[#All],12,FALSE) -> R1013 | I5: =VLOOKUP(Hospitalisation_Details[[#This Row],[Customer ID]],Hospitalisation_Details[#All],12,FALSE) -> R1013 | J5: =VLOOKUP(Hospitalisation_Details[[#This Row],[Customer ID]],Hospitalisation_Details[#All],11,FALSE) -> Tier - 3 | K5: =VLOOKUP(Hospitalisation_Details[[#This Row],[Customer ID]],Hospitalisation_Details[#All],9,FALSE) -> 604.54 | L5: =VLOOKUP(Medical_Examinations[[#This Row],[Customer ID]],Medical_Examinations[#All],2,FALSE) -> 38.095 | M5: =VLOOKUP(Medical_Examinations[[#This Row],[Customer ID]],Medical_Examinations[#All],3,FALSE) -> Obesity | N5: =VLOOKUP(Medical_Examinations[[#This Row],[Customer ID]],Medical_Examinations[#All],4,FALSE) -> 6.05 | O5: =VLOOKUP(Medical_Examinations[[#This Row],[Customer ID]],Medical_Examinations[#All],5,FALSE) -> Prediabetes | P5: =VLOOKUP(Medical_Examinations[[#This Row],[Customer ID]],Medical_Examinations[#All],6,FALSE) -> No | Q5: =VLOOKUP(Medical_Examinations[[#This Row],[Customer ID]],Medical_Examinations[#All],7,FALSE) -> No | R5: =VLOOKUP(Medical_Examinations[[#This Row],[Customer ID]],Medical_Examinations[#All],8,FALSE) -> No | S5: =VLOOKUP(Medical_Examinations[[#This Row],[Customer ID]],Medical_Examinations[#All],9,FALSE) -> 0 | T5: =VLOOKUP(Medical_Examinations[[#This Row],[Customer ID]],'Medical Examinations'!A4:J2339,10,FALSE) -> Yes
A6: ID5 | B6: Id5 | C6: Ms. | D6: Kristyn | E6: Kadala | F6: =VLOOKUP(Hospitalisation_Details[[#This Row],[Customer ID]],Hospitalisation_Details[#All],6,FALSE) -> 27-07-98 | G6: =VLOOKUP(Hospitalisation_Details[[#This Row],[Customer ID]],Hospitalisation_Details[#All],8,FALSE) -> 24 | H6: =VLOOKUP(Hospitalisation_Details[[#This Row],[Customer ID]],Hospitalisation_Details[#All],12,FALSE) -> R1013 | I6: =VLOOKUP(Hospitalisation_Details[[#This Row],[Customer ID]],Hospitalisation_Details[#All],12,FALSE) -> R1013 | J6: =VLOOKUP(Hospitalisation_Details[[#This Row],[Customer ID]],Hospitalisation_Details[#All],11,FALSE) -> Tier - 3 | K6: =VLOOKUP(Hospitalisation_Details[[#This Row],[Customer ID]],Hospitalisation_Details[#All],9,FALSE) -> 637.26 | L6: =VLOOKUP(Medical_Examinations[[#This Row],[Customer ID]],Medical_Examinations[#All],2,FALSE) -> 35.53 | M6: =VLOOKUP(Medical_Examinations[[#This Row],[Customer ID]],Medical_Examinations[#All],3,FALSE) -> Obesity | N6: =VLOOKUP(Medical_Examinations[[#This Row],[Customer ID]],Medical_Examinations[#All],4,FALSE) -> 5.45 | O6: =VLOOKUP(Medical_Examinations[[#This Row],[Customer ID]],Medical_Examinations[#All],5,FALSE) -> Normal | P6: =VLOOKUP(Medical_Examinations[[#This Row],[Customer ID]],Medical_Examinations[#All],6,FALSE) -> No | Q6: =VLOOKUP(Medical_Examinations[[#This Row],[Customer ID]],Medical_Examinations[#All],7,FALSE) -> No | R6: =VLOOKUP(Medical_Examinations[[#This Row],[Customer ID]],Medical_Examinations[#All],8,FALSE) -> No | S6: =VLOOKUP(Medical_Examinations[[#This Row],[Customer ID]],Medical_Examinations[#All],9,FALSE) -> 0 | T6: =VLOOKUP(Medical_Examinations[[#This Row],[Customer ID]],'Medical Examinations'!A5:J2340,10,FALSE) -> Yes
A7: ID6 | B7: Id6 | C7: Mr. | D7: Russell B. | E7: Baker | F7: =VLOOKUP(Hospitalisation_Details[[#This Row],[Customer ID]],Hospitalisation_Details[#All],6,FALSE) -> 20-11-01 | G7: =VLOOKUP(Hospitalisation_Details[[#This Row],[Customer ID]],Hospitalisation_Details[#All],8,FALSE) -> 21 | H7: =VLOOKUP(Hospitalisation_Details[[#This Row],[Customer ID]],Hospitalisation_Details[#All],12,FALSE) -> R1012 | I7: =VLOOKUP(Hospitalisation_Details[[#This Row],[Customer ID]],Hospitalisation_Details[#All],12,FALSE) -> R1012 | J7: =VLOOKUP(Hospitalisation_Details[[#This Row],[Customer ID]],Hospitalisation_Details[#All],11,FALSE) -> Tier - 3 | K7: =VLOOKUP(Hospitalisation_Details[[#This Row],[Customer ID]],Hospitalisation_Details[#All],9,FALSE) -> 646.14 | L7: =VLOOKUP(Medical_Examinations[[#This Row],[Customer ID]],Medical_Examinations[#All],2,FALSE) -> 32.8 | M7: =VLOOKUP(Medical_Examinations[[#This Row],[Customer ID]],Medical_Examinations[#All],3,FALSE) -> Obesity | N7: =VLOOKUP(Medical_Examinations[[#This Row],[Customer ID]],Medical_Examinations[#All],4,FALSE) -> 6.59 | O7: =VLOOKUP(Medical_Examinations[[#This Row],[Customer ID]],Medical_Examinations[#All],5,FALSE) -> Diabetes | P7: =VLOOKUP(Medical_Examinations[[#This Row],[Customer ID]],Medical_Examinations[#All],6,FALSE) -> No | Q7: =VLOOKUP(Medical_Examinations[[#This Row],[Customer ID]],Medical_Examinations[#All],7,FALSE) -> No | R7: =VLOOKUP(Medical_Examinations[[#This Row],[Customer ID]],Medical_Examinations[#All],8,FALSE) -> No | S7: =VLOOKUP(Medical_Examinations[[#This Row],[Customer ID]],Medical_Examinations[#All],9,FALSE) -> 0 | T7: =VLOOKUP(Medical_Examinations[[#This Row],[Customer ID]],'Medical Examinations'!A6:J2341,10,FALSE) -> Yes
A8: ID7 | B8: Id7 | C8: Mr. | D8: Scott | E8: Macpherson | F8: =VLOOKUP(Hospitalisation_Details[[#This Row],[Customer ID]],Hospitalisation_Details[#All],6,FALSE) -> 01-06-93 | G8: =VLOOKUP(Hospitalisation_Details[[#This Row],[Customer ID]],Hospitalisation_Details[#All],8,FALSE) -> 30 | H8: =VLOOKUP(Hospitalisation_Details[[#This Row],[Customer ID]],Hospitalisation_Details[#All],12,FALSE) -> R1013 | I8: =VLOOKUP(Hospitalisation_Details[[#This Row],[Customer ID]],Hospitalisation_Details[#All],12,FALSE) -> R1013 | J8: =VLOOKUP(Hospitalisation_Details[[#This Row],[Customer ID]],Hospitalisation_Details[#All],11,FALSE) -> Tier - 3 | K8: =VLOOKUP(Hospitalisation_Details[[#This Row],[Customer ID]],Hospitalisation_Details[#All],9,FALSE) -> 650 | L8: =VLOOKUP(Medical_Examinations[[#This Row],[Customer ID]],Medical_Examinations[#All],2,FALSE) -> 36.4 | M8: =VLOOKUP(Medical_Examinations[[#This Row],[Customer ID]],Medical_Examinations[#All],3,FALSE) -> Obesity | N8: =VLOOKUP(Medical_Examinations[[#This Row],[Customer ID]],Medical_Examinations[#All],4,FALSE) -> 6.07 | O8: =VLOOKUP(Medical_Examinations[[#This Row],[Customer ID]],Medical_Examinations[#All],5,FALSE) -> Prediabetes | P8: =VLOOKUP(Medical_Examinations[[#This Row],[Customer ID]],Medical_Examinations[#All],6,FALSE) -> No | Q8: =VLOOKUP(Medical_Examinations[[#This Row],[Customer ID]],Medical_Examinations[#All],7,FALSE) -> No | R8: =VLOOKUP(Medical_Examinations[[#This Row],[Customer ID]],Medical_Examinations[#All],8,FALSE) -> No | S8: =VLOOKUP(Medical_Examinations[[#This Row],[Customer ID]],Medical_Examinations[#All],9,FALSE) -> 0 | T8: =VLOOKUP(Medical_Examinations[[#This Row],[Customer ID]],'Medical Examinations'!A7:J2342,10,FALSE) -> Yes
A9: ID8 | B9: Id8 | C9: Mr. | D9: Stephen | E9: Hallman | F9: =VLOOKUP(Hospitalisation_Details[[#This Row],[Customer ID]],Hospitalisation_Details[#All],6,FALSE) -> 04-07-95 | G9: =VLOOKUP(Hospitalisation_Details[[#This Row],[Customer ID]],Hospitalisation_Details[#All],8,FALSE) -> 27 | H9: =VLOOKUP(Hospitalisation_Details[[#This Row],[Customer ID]],Hospitalisation_Details[#All],12,FALSE) -> R1013 | I9: =VLOOKUP(Hospitalisation_Details[[#This Row],[Customer ID]],Hospitalisation_Details[#All],12,FALSE) -> R1013 | J9: =VLOOKUP(Hospitalisation_Details[[#This Row],[Customer ID]],Hospitalisation_Details[#All],11,FALSE) -> Tier - 3 | K9: =VLOOKUP(Hospitalisation_Details[[#This Row],[Customer ID]],Hospitalisation_Details[#All],9,FALSE) -> 650 | L9: =VLOOKUP(Medical_Examinations[[#This Row],[Customer ID]],Medical_Examinations[#All],2,FALSE) -> 36.96 | M9: =VLOOKUP(Medical_Examinations[[#This Row],[Customer ID]],Medical_Examinations[#All],3,FALSE) -> Obesity | N9: =VLOOKUP(Medical_Examinations[[#This Row],[Customer ID]],Medical_Examinations[#All],4,FALSE) -> 7.93 | O9: =VLOOKUP(Medical_Examinations[[#This Row],[Customer ID]],Medical_Examinations[#All],5,FALSE) -> Diabetes | P9: =VLOOKUP(Medical_Examinations[[#This Row],[Customer ID]],Medical_Examinations[#All],6,FALSE) -> No | Q9: =VLOOKUP(Medical_Examinations[[#This Row],[Customer ID]],Medical_Examinations[#All],7,FALSE) -> No | R9: =VLOOKUP(Medical_Examinations[[#This Row],[Customer ID]],Medical_Examinations[#All],8,FALSE) -> No | S9: =VLOOKUP(Medical_Examinations[[#This Row],[Customer ID]],Medical_Examinations[#All],9,FALSE) -> 3 | T9: =VLOOKUP(Medical_Examinations[[#This Row],[Customer ID]],'Medical Examinations'!A8:J2343,10,FALSE) -> Yes
A10: ID9 | B10: Id9 | C10: Mr. | D10: Patrick R. | E10: Moran | F10: =VLOOKUP(Hospitalisation_Details[[#This Row],[Customer ID]],Hospitalisation_Details[#All],6,FALSE) -> 29-11-02 | G10: =VLOOKUP(Hospitalisation_Details[[#This Row],[Customer ID]],Hospitalisation_Details[#All],8,FALSE) -> 20 | H10: =VLOOKUP(Hospitalisation_Details[[#This Row],[Customer ID]],Hospitalisation_Details[#All],12,FALSE) -> R1012 | I10: =VLOOKUP(Hospitalisation_Details[[#This Row],[Customer ID]],Hospitalisation_Details[#All],12,FALSE) -> R1012 | J10: =VLOOKUP(Hospitalisation_Details[[#This Row],[Customer ID]],Hospitalisation_Details[#All],11,FALSE) -> Tier - 2 | K10: =VLOOKUP(Hospitalisation_Details[[#This Row],[Customer ID]],Hospitalisation_Details[#All],9,FALSE) -> 668 | L10: =VLOOKUP(Medical_Examinations[[#This Row],[Customer ID]],Medical_Examinations[#All],2,FALSE) -> 41.14 | M10: =VLOOKUP(Medical_Examinations[[#This Row],[Customer ID]],Medical_Examinations[#All],3,FALSE) -> Obesity | N10: =VLOOKUP(Medical_Examinations[[#This Row],[Customer ID]],Medical_Examinations[#All],4,FALSE) -> 9.58 | O10: =VLOOKUP(Medical_Examinations[[#This Row],[Customer ID]],Medical_Examinations[#All],5,FALSE) -> Diabetes | P10: =VLOOKUP(Medical_Examinations[[#This Row],[Customer ID]],Medical_Examinations[#All],6,FALSE) -> Yes | Q10: =VLOOKUP(Medical_Examinations[[#This Row],[Customer ID]],Medical_Examinations[#All],7,FALSE) -> No | R10: =VLOOKUP(Medical_Examinations[[#This Row],[Customer ID]],Medical_Examinations[#All],8,FALSE) -> Yes | S10: =VLOOKUP(Medical_Examinations[[#This Row],[Customer ID]],Medical_Examinations[#All],9,FALSE) -> 1 | T10: =VLOOKUP(Medical_Examinations[[#This Row],[Customer ID]],'Medical Examinations'!A9:J2344,10,FALSE) -> Yes
A11: ID10 | B11: Id10 | C11: Ms. | D11: Brooke N. | E11: Benner | F11: =VLOOKUP(Hospitalisation_Details[[#This Row],[Customer ID]],Hospitalisation_Details[#All],6,FALSE) -> 09-11-97 | G11: =VLOOKUP(Hospitalisation_Details[[#This Row],[Customer ID]],Hospitalisation_Details[#All],8,FALSE) -> 25 | H11: =VLOOKUP(Hospitalisation_Details[[#This Row],[Customer ID]],Hospitalisation_Details[#All],12,FALSE) -> R1013 | I11: =VLOOKUP(Hospitalisation_Details[[#This Row],[Customer ID]],Hospitalisation_Details[#All],12,FALSE) -> R1013 | J11: =VLOOKUP(Hospitalisation_Details[[#This Row],[Customer ID]],Hospitalisation_Details[#All],11,FALSE) -> Tier - 3 | K11: =VLOOKUP(Hospitalisation_Details[[#This Row],[Customer ID]],Hospitalisation_Details[#All],9,FALSE) -> 670 | L11: =VLOOKUP(Medical_Examinations[[#This Row],[Customer ID]],Medical_Examinations[#All],2,FALSE) -> 38.06 | M11: =VLOOKUP(Medical_Examinations[[#This Row],[Customer ID]],Medical_Examinations[#All],3,FALSE) -> Obesity | N11: =VLOOKUP(Medical_Examinations[[#This Row],[Customer ID]],Medical_Examinations[#All],4,FALSE) -> 10.79 | O11: =VLOOKUP(Medical_Examinations[[#This Row],[Customer ID]],Medical_Examinations[#All],5,FALSE) -> Diabetes | P11: =VLOOKUP(Medical_Examinations[[#This Row],[Customer ID]],Medical_Examinations[#All],6,FALSE) -> No | Q11: =VLOOKUP(Medical_Examinations[[#This Row],[Customer ID]],Medical_Examinations[#All],7,FALSE) -> No | R11: =VLOOKUP(Medical_Examinations[[#This Row],[Customer ID]],Medical_Examinations[#All],8,FALSE) -> No | S11: =VLOOKUP(Medical_Examinations[[#This Row],[Customer ID]],Medical_Examinations[#All],9,FALSE) -> 0 | T11: =VLOOKUP(Medical_Examinations[[#This Row],[Customer ID]],'Medical Examinations'!A10:J2345,10,FALSE) -> Yes
A12: ID11 | B12: Id11 | C12: Ms. | D12: Paola Andrea | E12: Fierro Vargas | F12: =VLOOKUP(Hospitalisation_Details[[#This Row],[Customer ID]],Hospitalisation_Details[#All],6,FALSE) -> 12-09-01 | G12: =VLOOKUP(Hospitalisation_Details[[#This Row],[Customer ID]],Hospitalisation_Details[#All],8,FALSE) -> 21 | H12: =VLOOKUP(Hospitalisation_Details[[#This Row],[Customer ID]],Hospitalisation_Details[#All],12,FALSE) -> R1013 | I12: =VLOOKUP(Hospitalisation_Details[[#This Row],[Customer ID]],Hospitalisation_Details[#All],12,FALSE) -> R1013 | J12: =VLOOKUP(Hospitalisation_Details[[#This Row],[Customer ID]],Hospitalisation_Details[#All],11,FALSE) -> Tier - 2 | K12: =VLOOKUP(Hospitalisation_Details[[#This Row],[Customer ID]],Hospitalisation_Details[#All],9,FALSE) -> 687.54 | L12: =VLOOKUP(Medical_Examinations[[#This Row],[Customer ID]],Medical_Examinations[#All],2,FALSE) -> 37.7 | M12: =VLOOKUP(Medical_Examinations[[#This Row],[Customer ID]],Medical_Examinations[#All],3,FALSE) -> Obesity | N12: =VLOOKUP(Medical_Examinations[[#This Row],[Customer ID]],Medical_Examinations[#All],4,FALSE) -> 5.96 | O12: =VLOOKUP(Medical_Examinations[[#This Row],[Customer ID]],Medical_Examinations[#All],5,FALSE) -> Prediabetes | P12: =VLOOKUP(Medical_Examinations[[#This Row],[Customer ID]],Medical_Examinations[#All],6,FALSE) -> Yes | Q12: =VLOOKUP(Medical_Examinations[[#This Row],[Customer ID]],Medical_Examinations[#All],7,FALSE) -> No | R12: =VLOOKUP(Medical_Examinations[[#This Row],[Customer ID]],Medical_Examinations[#All],8,FALSE) -> No | S12: =VLOOKUP(Medical_Examinations[[#This Row],[Customer ID]],Medical_Examinations[#All],9,FALSE) -> 2 | T12: =VLOOKUP(Medical_Examinations[[#This Row],[Customer ID]],'Medical Examinations'!A11:J2346,10,FALSE) -> Yes
A13: ID12 | B13: Id12 | C13: Mr. | D13: David | E13: Franz | F13: =VLOOKUP(Hospitalisation_Details[[#This Row],[Customer ID]],Hospitalisation_Details[#All],6,FALSE) -> 26-12-99 | G13: =VLOOKUP(Hospitalisation_Details[[#This Row],[Customer ID]],Hospitalisation_Details[#All],8,FALSE) -> 23 | H13: =VLOOKUP(Hospitalisation_Details[[#This Row],[Customer ID]],Hospitalisation_Details[#All],12,FALSE) -> R1013 | I13: =VLOOKUP(Hospitalisation_Details[[#This Row],[Customer ID]],Hospitalisation_Details[#All],12,FALSE) -> R1013 | J13: =VLOOKUP(Hospitalisation_Details[[#This Row],[Customer ID]],Hospitalisation_Details[#All],11,FALSE) -> Tier - 3 | K13: =VLOOKUP(Hospitalisation_Details[[#This Row],[Customer ID]],Hospitalisation_Details[#All],9,FALSE) -> 700 | L13: =VLOOKUP(Medical_Examinations[[#This Row],[Customer ID]],Medical_Examinations[#All],2,FALSE) -> 42.13 | M13: =VLOOKUP(Medical_Examinations[[#This Row],[Customer ID]],Medical_Examinations[#All],3,FALSE) -> Obesity | N13: =VLOOKUP(Medical_Examinations[[#This Row],[Customer ID]],Medical_Examinations[#All],4,FALSE) -> 11.9 | O13: =VLOOKUP(Medical_Examinations[[#This Row],[Customer ID]],Medical_Examinations[#All],5,FALSE) -> Diabetes | P13: =VLOOKUP(Medical_Examinations[[#This Row],[Customer ID]],Medical_Examinations[#All],6,FALSE) -> No | Q13: =VLOOKUP(Medical_Examinations[[#This Row],[Customer ID]],Medical_Examinations[#All],7,FALSE) -> No | R13: =VLOOKUP(Medical_Examinations[[#This Row],[Customer ID]],Medical_Examinations[#All],8,FALSE) -> No | S13: =VLOOKUP(Medical_Examinations[[#This Row],[Customer ID]],Medical_Examinations[#All],9,FALSE) -> 0 | T13: =VLOOKUP(Medical_Examinations[[#This Row],[Customer ID]],'Medical Examinations'!A12:J2347,10,FALSE) -> Yes
... A2336: ID2335 | B2336: Id2335 | C2336: Mr. | D2336: Aaron K | E2336: German | F2336: =VLOOKUP(Hospitalisation_Details[[#This Row],[Customer ID]],Hospitalisation_Details[#All],6,FALSE) -> 04-09-63 | G2336: =VLOOKUP(Hospitalisation_Details[[#This Row],[Customer ID]],Hospitalisation_Details[#All],8,FALSE) -> 59 | H2336: =VLOOKUP(Hospitalisation_Details[[#This Row],[Customer ID]],Hospitalisation_Details[#All],12,FALSE) -> R1013 | I2336: =VLOOKUP(Hospitalisation_Details[[#This Row],[Customer ID]],Hospitalisation_Details[#All],12,FALSE) -> R1013 | J2336: =VLOOKUP(Hospitalisation_Details[[#This Row],[Customer ID]],Hospitalisation_Details[#All],11,FALSE) -> Tier - 2 | K2336: =VLOOKUP(Hospitalisation_Details[[#This Row],[Customer ID]],Hospitalisation_Details[#All],9,FALSE) -> 48970.25 | L2336: =VLOOKUP(Medical_Examinations[[#This Row],[Customer ID]],Medical_Examinations[#All],2,FALSE) -> 17.58 | M2336: =VLOOKUP(Medical_Examinations[[#This Row],[Customer ID]],Medical_Examinations[#All],3,FALSE) -> Underweight | N2336: =VLOOKUP(Medical_Examinations[[#This Row],[Customer ID]],Medical_Examinations[#All],4,FALSE) -> 4.51 | O2336: =VLOOKUP(Medical_Examinations[[#This Row],[Customer ID]],Medical_Examinations[#All],5,FALSE) -> Normal | P2336: =VLOOKUP(Medical_Examinations[[#This Row],[Customer ID]],Medical_Examinations[#All],6,FALSE) -> No | Q2336: =VLOOKUP(Medical_Examinations[[#This Row],[Customer ID]],Medical_Examinations[#All],7,FALSE) -> No | R2336: =VLOOKUP(Medical_Examinations[[#This Row],[Customer ID]],Medical_Examinations[#All],8,FALSE) -> No | S2336: =VLOOKUP(Medical_Examinations[[#This Row],[Customer ID]],Medical_Examinations[#All],9,FALSE) -> 1 | T2336: =VLOOKUP(Medical_Examinations[[#This Row],[Customer ID]],'Medical Examinations'!A2335:J4670,10,FALSE) -> No

Sheet work sheet
A3: Count of Customer ID | B3: Cancer History
A4: smoking status | B4: No | C4: Yes | D4: Grand Total
A5: No | B5: 1540 | C5: 404 | D5: 1944
A6: Yes | B6: 307 | C6: 84 | D6: 391
A7: Grand Total | B7: 1847 | C7: 488 | D7: 2335
A21: Tansplants | B21: Count of Number Of Major Surgeries | C21: Count of HBA1C
A22: yes | B22: 144 | C22: 144
A23: No | B23: 2191 | C23: 2191
A24: Grand Total | B24: 2335 | C24: 2335
A47: Diabetes Status | B47: Count of charges
A48: Diabetes | B48: 784
A49: Normal Weight | B49: 139
A50: Obesity | B50: 423
A51: Overweight | B51: 157
A52: Underweight | B52: 65
A53: Normal | B53: 1095
A54: Normal Weight | B54: 216
A55: Obesity | B55: 561
A56: Overweight | B56: 236
A57: Underweight | B57: 82
A58: Prediabetes | B58: 456
A59: Normal Weight | B59: 82
... A63: Grand Total | B63: 2335
A68: Average of charges | B68: Cancer History
A69: State ID | B69: R1011 | C69: R1012 | D69: R1013 | E69: R1014 | F69: R1015 | G69: R1016 | H69: R1017 | I69: R1018 | J69: R1019 | K69: R1020 | L69: R1021 | M69: R1022 | N69: R1023 | O69: R1024 | P69: R1025 | Q69: R1026 | R69: Unknown | S69: Grand Total
A70: R1011 | B70: 19352.867 | S70: 19352.867
A71: R1012 | C71: 11857.445 | S71: 11857.445
A72: R1013 | D72: 10227.804 | S72: 10227.804
A73: R1014 | E73: 13478.057 | S73: 13478.057
A74: R1015 | F74: 14489.801 | S74: 14489.801
A75: R1016 | G75: 13589.263 | S75: 13589.263
A76: R1017 | H76: 14806.108 | S76: 14806.108
A77: R1018 | I77: 13272.787 | S77: 13272.787
A78: R1019 | J78: 13633.143 | S78: 13633.143
A79: R1020 | K79: 9238.4983 | S79: 9238.4983
A80: R1021 | L80: 8933.3781 | S80: 8933.3781
A81: R1022 | M81: 10650.521 | S81: 10650.521
A82: R1023 | N82: 13786.149 | S82: 13786.149
A83: R1024 | O83: 12577.691 | S83: 12577.691
A84: R1025 | P84: 8788.7823 | S84: 8788.7823
...

Sheet Dashboard
A1: HEALTH CARE

Sheet Solution
B7: Data Cleaning:
B9: 1) Check for the number of missing values marked with '?' in each column of the “Medical Examinations” Table and "Hospitalization Details" Table.
C11: Customer ID | D11: BMI | E11: HBA1C | F11: Heart Issues | G11: Any Transplants | H11: Cancer history | I11: NumberOfMajorSurgeries | J11: smoker
C12: Id560 | D12: 23.98 | E12: 4.9 | F12: No | G12: No | H12: No | I12: No major surgery | J12: ?
C13: Id635 | D13: 25.175 | E13: 4.96 | F13: No | G13: yes | H13: No | I13: 1 | J13: ?
C15: Customer ID | D15: year | E15: month | F15: date | G15: children | H15: charges | I15: Hospital tier | J15: City tier | K15: State ID
C16: ? | D16: 2004 | E16: Nov | F16: 6 | G16: 0 | H16: 1137.01 | I16: tier - 3 | J16: tier - 1 | K16: R1013
C17: ? | D17: 1999 | E17: Jun | F17: 9 | G17: 1 | H17: 2775.19 | I17: tier - 2 | J17: tier - 1 | K17: R1012
C18: ? | D18: 1985 | E18: Dec | F18: 20 | G18: 2 | H18: 6203.9 | I18: tier - 1 | J18: tier - 2 | K18: R1012
C19: ? | D19: 2000 | E19: Oct | F19: 13 | G19: 0 | H19: 35585.58 | I19: tier - 1 | J19: tier - 2 | K19: R1011
C20: ? | D20: 1992 | E20: Oct | F20: 6 | G20: 0 | H20: 36837.47 | I20: tier - 1 | J20: tier - 2 | K20: R1011
C21: ? | D21: 1991 | E21: Nov | F21: 22 | G21: 2 | H21: 38711 | I21: tier - 1 | J21: tier - 3 | K21: R1011
C23: Customer ID | D23: year | E23: month | F23: date | G23: children | H23: charges | I23: Hospital tier | J23: City tier | K23: State ID
C24: Id2322 | D24: 2002 | E24: ? | F24: 19 | G24: 0 | H24: 750 | I24: tier - 3 | J24: tier - 1 | K24: R1012
C25: Id2318 | D25: 1996 | E25: ? | F25: 18 | G25: 0 | H25: 770.38 | I25: tier - 3 | J25: ? | K25: R1012
C26: Id3 | D26: 1970 | E26: ? | F26: 11 | G26: 3 | H26: 60021.4 | I26: tier - 1 | J26: tier - 1 | K26: R1012
C28: Customer ID | D28: year | E28: month | F28: date | G28: children | H28: charges | I28: Hospital tier | J28: City tier | K28: State ID
C29: Id1793 | D29: 1995 | E29: Dec | F29: 1 | G29: 3 | H29: 4827.9 | I29: tier - 1 | J29: tier - 2 | K29: ?
C30: Id170 | D30: 2000 | E30: Sep | F30: 5 | G30: 1 | H30: 37165.16 | I30: tier - 1 | J30: tier - 3 | K30: ?
C32: Customer ID | D32: year | E32: month | F32: date | G32: children | H32: charges | I32: Hospital tier | J32: City tier | K32: State ID
C33: Id2324 | D33: 1999 | E33: Dec | F33: 26 | G33: 0 | H33: 700 | I33: ? | J33: tier - 3 | K33: R1013
C35: smoker-2
C36: city tier-1
C37: state id -2
C38: hospital tier-1
C39: month-3
C40: customer id -6
B42: 2) Fill in the missing values of ‘month’ with Sep and ‘year’ with its average rounded to the nearest integer.
B43: 3) Determine the most frequently occurring values in the ‘smoker’, 'Hospital tier' and 'City tier' columns, and fill in the missing values accordingly.
B44: 4) If any 'State ID' values are missing, consider filling them with 'Unknown' or using another appropriate strategy.
C45: Customer ID | D45: year | E45: month | F45: date | G45: Date of Birth | H45: Date of Birth2 | I45: children | J45: Age | K45: charges | L45: Hospital tier | M45: City tier | N45: State ID
C46: ID2335 | D46: 1992 | E46: Jul | F46: 9 | G46: =_xlfn.CONCAT(Hospitalisation_Details10[[#This Row],[date]],"-",Hospitalisation_Details10[[#This Row],[month]],"-",Hospitalisation_Details10[[#This Row],[year]]) -> 9-Jul-1992 | H46: =TEXT(Hospitalisation_Details10[[#This Row],[Date of Birth]],"dd-mm-yy") -> 09-07-92 | I46: 0 | J46: =DATEDIF(Hospitalisation_Details10[[#This Row],[Date of Birth2]],DATE(2023,6,8),"y") -> 30 | K46: 563.84 | L46: Tier - 2 | M46: Tier - 3 | N46: R1013
C47: ID2334 | D47: 1992 | E47: Nov | F47: 30 | G47: =_xlfn.CONCAT(Hospitalisation_Details10[[#This Row],[date]],"-",Hospitalisation_Details10[[#This Row],[month]],"-",Hospitalisation_Details10[[#This Row],[year]]) -> 30-Nov-1992 | H47: =TEXT(Hospitalisation_Details10[[#This Row],[Date of Birth]],"dd-mm-yy") -> 30-11-92 | I47: 0 | J47: =DATEDIF(Hospitalisation_Details10[[#This Row],[Date of Birth2]],DATE(2023,6,8),"y") -> 30 | K47: 570.62 | L47: Tier - 2 | M47: Tier - 1 | N47: R1013
C48: ID2333 | D48: 1993 | E48: Jun | F48: 30 | G48: =_xlfn.CONCAT(Hospitalisation_Details10[[#This Row],[date]],"-",Hospitalisation_Details10[[#This Row],[month]],"-",Hospitalisation_Details10[[#This Row],[year]]) -> 30-Jun-1993 | H48: =TEXT(Hospitalisation_Details10[[#This Row],[Date of Birth]],"dd-mm-yy") -> 30-06-93 | I48: 0 | J48: =DATEDIF(Hospitalisation_Details10[[#This Row],[Date of Birth2]],DATE(2023,6,8),"y") -> 29 | K48: 600 | L48: Tier - 2 | M48: Tier - 1 | N48: R1013
C49: ID2332 | D49: 1992 | E49: Sep | F49: 13 | G49: =_xlfn.CONCAT(Hospitalisation_Details10[[#This Row],[date]],"-",Hospitalisation_Details10[[#This Row],[month]],"-",Hospitalisation_Details10[[#This Row],[year]]) -> 13-Sep-1992 | H49: =TEXT(Hospitalisation_Details10[[#This Row],[Date of Birth]],"dd-mm-yy") -> 13-09-92 | I49: 0 | J49: =DATEDIF(Hospitalisation_Details10[[#This Row],[Date of Birth2]],DATE(2023,6,8),"y") -> 30 | K49: 604.54 | L49: Tier - 3 | M49: Tier - 3 | N49: R1013
C50: ID2331 | D50: 1998 | E50: Jul | F50: 27 | G50: =_xlfn.CONCAT(Hospitalisation_Details10[[#This Row],[date]],"-",Hospitalisation_Details10[[#This Row],[month]],"-",Hospitalisation_Details10[[#This Row],[year]]) -> 27-Jul-1998 | H50: =TEXT(Hospitalisation_Details10[[#This Row],[Date of Birth]],"dd-mm-yy") -> 27-07-98 | I50: 0 | J50: =DATEDIF(Hospitalisation_Details10[[#This Row],[Date of Birth2]],DATE(2023,6,8),"y") -> 24 | K50: 637.26 | L50: Tier - 3 | M50: Tier - 3 | N50: R1013
C51: ID2330 | D51: 2001 | E51: Nov | F51: 20 | G51: =_xlfn.CONCAT(Hospitalisation_Details10[[#This Row],[date]],"-",Hospitalisation_Details10[[#This Row],[month]],"-",Hospitalisation_Details10[[#This Row],[year]]) -> 20-Nov-2001 | H51: =TEXT(Hospitalisation_Details10[[#This Row],[Date of Birth]],"dd-mm-yy") -> 20-11-01 | I51: 0 | J51: =DATEDIF(Hospitalisation_Details10[[#This Row],[Date of Birth2]],DATE(2023,6,8),"y") -> 21 | K51: 646.14 | L51: Tier - 3 | M51: Tier - 3 | N51: R1012
C52: ID2329 | D52: 1993 | E52: Jun | F52: 1 | G52: =_xlfn.CONCAT(Hospitalisation_Details10[[#This Row],[date]],"-",Hospitalisation_Details10[[#This Row],[month]],"-",Hospitalisation_Details10[[#This Row],[year]]) -> 1-Jun-1993 | H52: =TEXT(Hospitalisation_Details10[[#This Row],[Date of Birth]],"dd-mm-yy") -> 01-06-93 | I52: 0 | J52: =DATEDIF(Hospitalisation_Details10[[#This Row],[Date of Birth2]],DATE(2023,6,8),"y") -> 30 | K52: 650 | L52: Tier - 3 | M52: Tier - 3 | N52: R1013
C53: ID2328 | D53: 1995 | E53: Jul | F53: 4 | G53: =_xlfn.CONCAT(Hospitalisation_Details10[[#This Row],[date]],"-",Hospitalisation_Details10[[#This Row],[month]],"-",Hospitalisation_Details10[[#This Row],[year]]) -> 4-Jul-1995 | H53: =TEXT(Hospitalisation_Details10[[#This Row],[Date of Birth]],"dd-mm-yy") -> 04-07-95 | I53: 0 | J53: =DATEDIF(Hospitalisation_Details10[[#This Row],[Date of Birth2]],DATE(2023,6,8),"y") -> 27 | K53: 650 | L53: Tier - 3 | M53: Tier - 3 | N53: R1013
C54: ID2327 | D54: 2002 | E54: Nov | F54: 29 | G54: =_xlfn.CONCAT(Hospitalisation_Details10[[#This Row],[date]],"-",Hospitalisation_Details10[[#This Row],[month]],"-",Hospitalisation_Details10[[#This Row],[year]]) -> 29-Nov-2002 | H54: =TEXT(Hospitalisation_Details10[[#This Row],[Date of Birth]],"dd-mm-yy") -> 29-11-02 | I54: 0 | J54: =DATEDIF(Hospitalisation_Details10[[#This Row],[Date of Birth2]],DATE(2023,6,8),"y") -> 20 | K54: 668 | L54: Tier - 3 | M54: Tier - 2 | N54: R1012
...
